Workbook

Sheet Executive_Summary
A1: NHANES 2017-2018 public-use survey data. Descriptive care-gap monitoring, not a certified quality measure, not clinical guidance, and no respondent-level rows.
A2: Executive summary: five decision metrics for diabetes care-gap monitoring
A3: Values are read from the pipeline outputs; the Check column re-reads the same value from the detail sheet.
A4: Pipeline refresh: 2026-09-19T05:18:21+00:00. Source files retrieved: 2026-09-19. Code commit: 0fc4a7ad68c18268cad6e98fcdd02bf0edf3fdfa.
A5: metric | B5: value | C5: ci_low | D5: ci_high | E5: unit | F5: n_basis | G5: unweighted_n | H5: effective_n | I5: definition | J5: source | K5: check
A6: Undiagnosed share, all groups | B6: 0.18885011 | C6: 0.15541031 | D6: 0.22754666 | E6: share of HbA1c-positive people | F6: HbA1c-positive respondents | G6: 711 | H6: 271.0185 | I6: Weighted share of people meeting the HbA1c criterion who were never told by a doctor that they have diabetes. | J6: undiagnosis_estimates.csv | K6: =IF(ABS(B6-Care_Gaps!F12)<=1e-06,"PASS","FAIL") -> PASS
A7: People with undiagnosed diabetes, weighted | B7: 4245381.2 | E7: people (survey-weighted) | F7: undiagnosed respondents | G7: 152 | I7: Survey-weighted count of people meeting the HbA1c criterion who were never told they have diabetes. | J7: group_summary.csv | K7: =IF(ABS(B7-Care_Gaps!E12)<=0.5,"PASS","FAIL") -> PASS
A8: Undiagnosed share, Non-Hispanic Black | B8: 0.32236148 | C8: 0.23031295 | D8: 0.43061657 | E8: share of HbA1c-positive people | F8: HbA1c-positive respondents | G8: 181 | H8: 140.92246 | I8: Weighted share of people meeting the HbA1c criterion who were never told by a doctor that they have diabetes. | J8: undiagnosis_estimates.csv | K8: =IF(ABS(B8-Care_Gaps!F7)<=1e-06,"PASS","FAIL") -> PASS
A9: Difference versus Non-Hispanic White (pre-specified) | B9: 0.19386723 | C9: 0.070202964 | D9: 0.31753149 | E9: percentage points | F9: HbA1c-positive respondents, comparison group | G9: 181 | H9: 140.92246 | I9: Undiagnosed share of a group minus the undiagnosed share of the reference group (Non-Hispanic White). | J9: undiagnosis_contrasts.csv | K9: =IF(ABS(B9-Subgroup_Review!H7)<=1e-06,"PASS","FAIL") -> PASS
A10: Specificity cost of the HbA1c label, Non-Hispanic Black, race-included model | B10: 0.099753617 | C10: 0.085736919 | D10: 0.11215376 | E10: percentage points | F10: HbA1c-negative respondents | G10: 1131 | H10: 874.06343 | I10: Specificity of the model trained on the diagnosed label minus specificity of the model trained on the HbA1c label. Positive means more false positives when training on the HbA1c label. | J10: specificity_cost.csv | K10: =IF(ABS(B10-Model_Tradeoffs!E84)<=1e-06,"PASS","FAIL") -> PASS
A12: Reconciliation status by sheet
A13: Cohort_Flow | B13: =Cohort_Flow!B36 -> ALL CHECKS PASS
A14: Care_Gaps | B14: =IF(COUNTIF(Care_Gaps!O6:P12,"FAIL")=0,"ALL CHECKS PASS","REVIEW") -> ALL CHECKS PASS
A15: Subgroup_Review | B15: =IF(COUNTIF(Subgroup_Review!S6:S11,"FAIL")=0,"ALL CHECKS PASS","REVIEW") -> ALL CHECKS PASS
A16: Model_Tradeoffs | B16: =IF(COUNTIF(Model_Tradeoffs!K76:K103,"FAIL")+COUNTIF(Model_Tradeoffs!Q6:Q9,"FAIL")=0,"ALL CHECKS PASS","REVIEW") -> ALL CHECKS PASS
A17: Data_Quality | B17: =IF(COUNTIF(Data_Quality!C6:C19,"FAIL")=0,"ALL CHECKS PASS","REVIEW") -> ALL CHECKS PASS
A18: Executive_Summary | B18: =IF(COUNTIF(K6:K10,"FAIL")=0,"ALL CHECKS PASS","REVIEW") -> ALL CHECKS PASS
A20: Population
A21: The analysis cohort represents the US civilian non-institutionalized population aged 12 and older with an exam weight, a valid diabetes questionnaire answer, a measured HbA1c and a known race and ethnicity group.
A23: Limitations
A24: 1. The undiagnosis gap is descriptive. It can reflect access to care, screening frequency, clinician behavior, insurance or measurement, and this data cannot separate them.
A25: 2. HbA1c is one of three ADA diagnostic criteria. Fasting glucose is not used, and HbA1c can read high in some people with sickle cell trait.
A26: 3. The models are minimal comparisons of two labels. They are not clinical risk models and are not ready for deployment.
A27: 4. Only the Non-Hispanic Black versus Non-Hispanic White comparison was named in advance. Every other subgroup comparison is exploratory and carries a Holm-adjusted p-value.
A28: 5. Small groups have wide intervals. A group with a small effective sample size is flagged, not hidden.
A29: 6. This is public research data, not an EHR extract. It is care-gap monitoring inspired by quality measurement, not a certified HEDIS measure.

Sheet Cohort_Flow
A1: NHANES 2017-2018 public-use survey data. Descriptive care-gap monitoring, not a certified quality measure, not clinical guidance, and no respondent-level rows.
A2: Cohort flow: from all NHANES participants to the analysis cohort
A3: Each step's remaining count comes from cohort_attrition.csv. Removed is re-derived by formula and reconciled below.
A5: criterion | B5: step | C5: remaining | D5: removed | E5: removed_check | F5: share_of_start | G5: removed_reconciles
A6: NHANES 2017-2018 participants (DEMO_J) | B6: 1 | C6: 9254 | D6: 0 | E6: =0 -> 0 | F6: =C6/C$6 -> 1 | G6: =IF(D6=E6,"PASS","FAIL") -> PASS
A7: Examined, with a positive MEC exam weight | B7: 2 | C7: 8704 | D7: 550 | E7: =C6-C7 -> 550 | F7: =C7/C$6 -> 0.94056624 | G7: =IF(D7=E7,"PASS","FAIL") -> PASS
A8: Meets the minimum age | B8: 3 | C8: 8704 | D8: 0 | E8: =C7-C8 -> 0 | F8: =C8/C$6 -> 0.94056624 | G8: =IF(D8=E8,"PASS","FAIL") -> PASS
A9: Valid diabetes questionnaire answer (yes, no or borderline) | B9: 4 | C9: 8362 | D9: 342 | E9: =C8-C9 -> 342 | F9: =C9/C$6 -> 0.90360925 | G9: =IF(D9=E9,"PASS","FAIL") -> PASS
A10: Borderline answers handled per the analysis variant | B10: 5 | C10: 8187 | D10: 175 | E10: =C9-C10 -> 175 | F10: =C10/C$6 -> 0.88469851 | G10: =IF(D10=E10,"PASS","FAIL") -> PASS
A11: HbA1c measured | B11: 6 | C11: 5873 | D11: 2314 | E11: =C10-C11 -> 2314 | F11: =C11/C$6 -> 0.63464448 | G11: =IF(D11=E11,"PASS","FAIL") -> PASS
A12: Known race and ethnicity (analysis cohort) | B12: 7 | C12: 5873 | D12: 0 | E12: =C11-C12 -> 0 | F12: =C12/C$6 -> 0.63464448 | G12: =IF(D12=E12,"PASS","FAIL") -> PASS
A16: Analysis cohort by group (summary counts, no respondent rows)
A17: group | B17: respondents | C17: weighted_population | D17: hba1c_positive_respondents | E17: diagnosed_among_positive | F17: undiagnosed_among_positive
A18: Non-Hispanic White | B18: 2022 | C18: 1.5559963e+08 | D18: 203 | E18: 184 | F18: 19
A19: Non-Hispanic Black | B19: 1312 | C19: 27992878 | D19: 181 | E19: 131 | F19: 50
A20: Mexican American | B20: 856 | C20: 25031701 | D20: 112 | E20: 87 | F20: 25
A21: Other Hispanic | B21: 546 | C21: 18123126 | D21: 74 | E21: 54 | F21: 20
A22: Non-Hispanic Asian | B22: 796 | C22: 14056292 | D22: 102 | E22: 73 | F22: 29
A23: Other/Multiracial | B23: 341 | C23: 12754182 | D23: 39 | E23: 30 | F23: 9
A24: All groups | B24: 5873 | C24: 2.535578e+08 | D24: 711 | E24: 559 | F24: 152
A28: Reconciliation
A29: check | B29: workbook_value | C29: pipeline_value | D29: abs_difference | E29: status
A30: First step equals participants in run_manifest.json | B30: =C6 -> 9254 | C30: 9254 | D30: =ABS(B30-C30) -> 0 | E30: =IF(D30<=1e-06,"PASS","FAIL") -> PASS
A31: Last step equals analysis cohort in run_manifest.json | B31: =C12 -> 5873 | C31: 5873 | D31: =ABS(B31-C31) -> 0 | E31: =IF(D31<=1e-06,"PASS","FAIL") -> PASS
A32: Sum of group respondents equals the last step | B32: =SUM(B18:B23) -> 5873 | C32: =C12 -> 5873 | D32: =ABS(B32-C32) -> 0 | E32: =IF(D32<=1e-06,"PASS","FAIL") -> PASS
A33: All groups row equals the sum of groups | B33: =B24 -> 5873 | C33: =SUM(B18:B23) -> 5873 | D33: =ABS(B33-C33) -> 0 | E33: =IF(D33<=1e-06,"PASS","FAIL") -> PASS
A34: Diagnosed plus undiagnosed equals HbA1c positives (All groups) | B34: =E24+F24 -> 711 | C34: =D24 -> 711 | D34: =ABS(B34-C34) -> 0 | E34: =IF(D34<=1e-06,"PASS","FAIL") -> PASS
A35: Total removed equals first minus last step | B35: =SUM(D6:D12) -> 3381 | C35: =C6-C12 -> 3381 | D35: =ABS(B35-C35) -> 0 | E35: =IF(D35<=1e-06,"PASS","FAIL") -> PASS
A36: Overall | B36: =IF(COUNTIF(E30:E35,"FAIL")=0,"ALL CHECKS PASS","REVIEW") -> ALL CHECKS PASS

Sheet Care_Gaps
A1: NHANES 2017-2018 public-use survey data. Descriptive care-gap monitoring, not a certified quality measure, not clinical guidance, and no respondent-level rows.
A2: Care gaps: undiagnosed diabetes among people meeting the HbA1c criterion
A3: Weighted estimate with a 95% logit interval, unweighted n and Kish effective n. Rows flagged SMALL SAMPLE have wide intervals.
A5: group | B5: hba1c_positive_respondents | C5: undiagnosed_respondents | D5: weighted_denominator | E5: weighted_undiagnosed | F5: estimate | G5: ci_low | H5: ci_high | I5: effective_n_kish | J5: small_sample_warning | K5: respondents_per_group_summary | L5: unweighted_share | M5: weighted_share_check | N5: ci_width | O5: estimate_reconciles | P5: n_reconciles
A6: Non-Hispanic White | B6: 203 | C6: 19 | D6: 12789945 | E6: 1643434.4 | F6: 0.12849425 | G6: 0.075352254 | H6: 0.21057921 | I6: 104.60038 | J6: OK | K6: 203 | L6: =C6/B6 -> 0.093596059 | M6: =E6/D6 -> 0.12849425 | N6: =H6-G6 -> 0.13522696 | O6: =IF(ABS(M6-F6)<=1e-06,"PASS","FAIL") -> PASS | P6: =IF(B6=K6,"PASS","FAIL") -> PASS
A7: Non-Hispanic Black | B7: 181 | C7: 50 | D7: 3215432 | E7: 1036531.4 | F7: 0.32236148 | G7: 0.23031295 | H7: 0.43061657 | I7: 140.92246 | J7: OK | K7: 181 | L7: =C7/B7 -> 0.27624309 | M7: =E7/D7 -> 0.32236148 | N7: =H7-G7 -> 0.20030362 | O7: =IF(ABS(M7-F7)<=1e-06,"PASS","FAIL") -> PASS | P7: =IF(B7=K7,"PASS","FAIL") -> PASS
A8: Mexican American | B8: 112 | C8: 25 | D8: 2179448.8 | E8: 494559.49 | F8: 0.22691953 | G8: 0.12944976 | H8: 0.36685268 | I8: 70.726598 | J8: OK | K8: 112 | L8: =C8/B8 -> 0.22321429 | M8: =E8/D8 -> 0.22691953 | N8: =H8-G8 -> 0.23740292 | O8: =IF(ABS(M8-F8)<=1e-06,"PASS","FAIL") -> PASS | P8: =IF(B8=K8,"PASS","FAIL") -> PASS
A9: Other Hispanic | B9: 74 | C9: 20 | D9: 1460659.7 | E9: 459954.27 | F9: 0.31489489 | G9: 0.13801422 | H9: 0.56886338 | I9: 53.369088 | J9: OK | K9: 74 | L9: =C9/B9 -> 0.27027027 | M9: =E9/D9 -> 0.31489489 | N9: =H9-G9 -> 0.43084916 | O9: =IF(ABS(M9-F9)<=1e-06,"PASS","FAIL") -> PASS | P9: =IF(B9=K9,"PASS","FAIL") -> PASS
A10: Non-Hispanic Asian | B10: 102 | C10: 29 | D10: 1619475.6 | E10: 448987.31 | F10: 0.2772424 | G10: 0.18395423 | H10: 0.39494332 | I10: 88.868673 | J10: OK | K10: 102 | L10: =C10/B10 -> 0.28431373 | M10: =E10/D10 -> 0.2772424 | N10: =H10-G10 -> 0.21098909 | O10: =IF(ABS(M10-F10)<=1e-06,"PASS","FAIL") -> PASS | P10: =IF(B10=K10,"PASS","FAIL") -> PASS
A11: Other/Multiracial | B11: 39 | C11: 9 | D11: 1215201.2 | E11: 161914.32 | F11: 0.13324074 | G11: 0.055520979 | H11: 0.28672678 | I11: 16.269939 | J11: SMALL SAMPLE | K11: 39 | L11: =C11/B11 -> 0.23076923 | M11: =E11/D11 -> 0.13324074 | N11: =H11-G11 -> 0.2312058 | O11: =IF(ABS(M11-F11)<=1e-06,"PASS","FAIL") -> PASS | P11: =IF(B11=K11,"PASS","FAIL") -> PASS
A12: All groups | B12: 711 | C12: 152 | D12: 22480162 | E12: 4245381.2 | F12: 0.18885011 | G12: 0.15541031 | H12: 0.22754666 | I12: 271.0185 | J12: OK | K12: 711 | L12: =C12/B12 -> 0.2137834 | M12: =E12/D12 -> 0.18885011 | N12: =H12-G12 -> 0.072136345 | O12: =IF(ABS(M12-F12)<=1e-06,"PASS","FAIL") -> PASS | P12: =IF(B12=K12,"PASS","FAIL") -> PASS
A14: Weighted undiagnosed share and people counts reconcile to group_summary.csv and undiagnosis_estimates.csv. Unweighted share is shown for context only.

Sheet Subgroup_Review
A1: NHANES 2017-2018 public-use survey data. Descriptive care-gap monitoring, not a certified quality measure, not clinical guidance, and no respondent-level rows.
A2: Subgroup review: undiagnosed share by group and comparison with the reference group
A3: Only the pre-specified comparison is confirmatory. Every other comparison is exploratory and labelled with its Holm-adjusted p-value (labels use 0.05 as a display convention).
A5: group | B5: hba1c_positive_respondents | C5: effective_n_kish | D5: small_sample_warning | E5: estimate | F5: ci_low | G5: ci_high | H5: difference | I5: diff_ci_low | J5: diff_ci_high | K5: ratio | L5: ratio_ci_low | M5: ratio_ci_high | N5: p_value | O5: p_value_holm | P5: analysis_type | Q5: review_label | R5: interval_excludes_zero | S5: holm_at_least_raw_p
A6: Non-Hispanic White | B6: 203 | C6: 104.60038 | D6: OK | E6: 0.12849425 | F6: 0.075352254 | G6: 0.21057921 | Q6: =IF(P6="","Reference group",IF(P6="confirmatory","Pre-specified comparison","Exploratory: "&IF(O6<0.05,"below 0.05 after Holm adjustment","not below 0.05 after Holm adjustment"))) -> Reference group | R6: =IF(H6="","",IF(OR(I6>0,J6<0),"YES","NO")) | S6: =IF(N6="","",IF(O6>=N6-1e-06,"PASS","FAIL"))
A7: Non-Hispanic Black | B7: 181 | C7: 140.92246 | D7: OK | E7: 0.32236148 | F7: 0.23031295 | G7: 0.43061657 | H7: 0.19386723 | I7: 0.070202964 | J7: 0.31753149 | K7: 2.5087619 | L7: 1.3418864 | M7: 4.6903271 | N7: 0.0044629132 | O7: 0.022314566 | P7: confirmatory | Q7: =IF(P7="","Reference group",IF(P7="confirmatory","Pre-specified comparison","Exploratory: "&IF(O7<0.05,"below 0.05 after Holm adjustment","not below 0.05 after Holm adjustment"))) -> Pre-specified comparison | R7: =IF(H7="","",IF(OR(I7>0,J7<0),"YES","NO")) -> YES | S7: =IF(N7="","",IF(O7>=N7-1e-06,"PASS","FAIL")) -> PASS
A8: Mexican American | B8: 112 | C8: 70.726598 | D8: OK | E8: 0.22691953 | F8: 0.12944976 | G8: 0.36685268 | H8: 0.098425276 | I8: -0.05885746 | J8: 0.25570801 | K8: 1.7659897 | L8: 0.72114716 | M8: 4.3246648 | N8: 0.20215939 | O8: 0.40431878 | P8: exploratory | Q8: =IF(P8="","Reference group",IF(P8="confirmatory","Pre-specified comparison","Exploratory: "&IF(O8<0.05,"below 0.05 after Holm adjustment","not below 0.05 after Holm adjustment"))) -> Exploratory: not below 0.05 after Holm adjustment | R8: =IF(H8="","",IF(OR(I8>0,J8<0),"YES","NO")) -> NO | S8: =IF(N8="","",IF(O8>=N8-1e-06,"PASS","FAIL")) -> PASS
A9: Other Hispanic | B9: 74 | C9: 53.369088 | D9: OK | E9: 0.31489489 | F9: 0.13801422 | G9: 0.56886338 | H9: 0.18640064 | I9: -0.042066051 | J9: 0.41486733 | K9: 2.4506536 | L9: 1.0023769 | M9: 5.9914616 | N9: 0.10250948 | O9: 0.30752845 | P9: exploratory | Q9: =IF(P9="","Reference group",IF(P9="confirmatory","Pre-specified comparison","Exploratory: "&IF(O9<0.05,"below 0.05 after Holm adjustment","not below 0.05 after Holm adjustment"))) -> Exploratory: not below 0.05 after Holm adjustment | R9: =IF(H9="","",IF(OR(I9>0,J9<0),"YES","NO")) -> NO | S9: =IF(N9="","",IF(O9>=N9-1e-06,"PASS","FAIL")) -> PASS
A10: Non-Hispanic Asian | B10: 102 | C10: 88.868673 | D10: OK | E10: 0.2772424 | F10: 0.18395423 | G10: 0.39494332 | H10: 0.14874815 | I10: 0.020976161 | J10: 0.27652015 | K10: 2.157625 | L10: 1.1086571 | M10: 4.1990852 | N10: 0.025423044 | O10: 0.10169218 | P10: exploratory | Q10: =IF(P10="","Reference group",IF(P10="confirmatory","Pre-specified comparison","Exploratory: "&IF(O10<0.05,"below 0.05 after Holm adjustment","not below 0.05 after Holm adjustment"))) -> Exploratory: not below 0.05 after Holm adjustment | R10: =IF(H10="","",IF(OR(I10>0,J10<0),"YES","NO")) -> YES | S10: =IF(N10="","",IF(O10>=N10-1e-06,"PASS","FAIL")) -> PASS
A11: Other/Multiracial | B11: 39 | C11: 16.269939 | D11: SMALL SAMPLE | E11: 0.13324074 | F11: 0.055520979 | G11: 0.28672678 | H11: 0.0047464952 | I11: -0.10482697 | J11: 0.11431996 | K11: 1.0369394 | L11: 0.4522368 | M11: 2.3776111 | N11: 0.92729334 | O11: 0.92729334 | P11: exploratory | Q11: =IF(P11="","Reference group",IF(P11="confirmatory","Pre-specified comparison","Exploratory: "&IF(O11<0.05,"below 0.05 after Holm adjustment","not below 0.05 after Holm adjustment"))) -> Exploratory: not below 0.05 after Holm adjustment | R11: =IF(H11="","",IF(OR(I11>0,J11<0),"YES","NO")) -> NO | S11: =IF(N11="","",IF(O11>=N11-1e-06,"PASS","FAIL")) -> PASS
A13: Difference is the group's undiagnosed share minus the reference group's, in percentage points. Intervals are 95%.

Sheet Model_Tradeoffs
A1: NHANES 2017-2018 public-use survey data. Descriptive care-gap monitoring, not a certified quality measure, not clinical guidance, and no respondent-level rows.
A2: Model tradeoffs: does the training label change who a screening model misses or over-flags?
A3: Both labels are scored against the HbA1c criterion. False-positive rate is one minus specificity and is a formula. Not clinical risk models.
A5: model | B5: role | C5: description | D5: auc_diagnosed_label | E5: auc_diagnosed_ci_low | F5: auc_diagnosed_ci_high | G5: auc_hba1c_label | H5: auc_hba1c_ci_low | I5: auc_hba1c_ci_high | J5: auc_difference | K5: auc_diff_ci_low | L5: auc_diff_ci_high | M5: p_value_bootstrap | N5: cost | O5: cost_ci_low | P5: cost_ci_high | Q5: auc_difference_reconciles
A6: demographic_logistic | B6: primary | C6: Age and sex, race excluded (primary benchmark) | D6: 0.75750159 | E6: 0.734551 | F6: 0.78485316 | G6: 0.75643291 | H6: 0.73400714 | I6: 0.78407285 | J6: 0.0010686852 | K6: -0.00039659605 | L6: 0.0025114161 | M6: 0.156 | N6: 0.0071060243 | O6: -0.0030141822 | P6: 0.018115901 | Q6: =IF(ABS((D6-G6)-J6)<=1e-06,"PASS","FAIL") -> PASS
A7: demographic_race_logistic | B7: sensitivity | C7: Age, sex and race dummies (sensitivity) | D7: 0.76314506 | E7: 0.73669993 | F7: 0.79661621 | G7: 0.76475809 | H7: 0.73679497 | I7: 0.80436876 | J7: -0.0016130281 | K7: -0.010099897 | L7: 0.0054156446 | M7: 0.692 | N7: 0.01357418 | O7: -0.0057127478 | P7: 0.031759925 | Q7: =IF(ABS((D7-G7)-J7)<=1e-06,"PASS","FAIL") -> PASS
A8: extended_logistic | B8: sensitivity | C8: Adds BMI, family history, insurance and a routine care place; race excluded | D8: 0.81872839 | E8: 0.79859208 | F8: 0.84665119 | G8: 0.81928471 | H8: 0.79850646 | I8: 0.84717732 | J8: -0.00055632648 | K8: -0.005628868 | L8: 0.0040327984 | M8: 0.864 | N8: 0.01558459 | O8: 0.0018659683 | P8: 0.031275434 | Q8: =IF(ABS((D8-G8)-J8)<=1e-06,"PASS","FAIL") -> PASS
A9: extended_boosting | B9: comparison | C9: Gradient boosting on the extended features, to test whether nonlinearity adds value | D9: 0.81100481 | E9: 0.787102 | F9: 0.84293512 | G9: 0.80864309 | H9: 0.78841138 | I9: 0.83581732 | J9: 0.0023617119 | K9: -0.0077100201 | L9: 0.013402058 | M9: 0.712 | N9: -0.022244562 | O9: -0.037068081 | P9: -0.0084033658 | Q9: =IF(ABS((D9-G9)-J9)<=1e-06,"PASS","FAIL") -> PASS
A13: Sensitivity, specificity and false-positive rate by model, group and label
A14: model | B14: group | C14: label | D14: respondents | E14: positives | F14: negatives | G14: effective_n_positives | H14: small_sample_warning | I14: sensitivity | J14: sensitivity_ci_low | K14: sensitivity_ci_high | L14: specificity | M14: specificity_ci_low | N14: specificity_ci_high | O14: ppv | P14: npv | Q14: false_positive_rate | R14: false_positive_rate_ci_low | S14: false_positive_rate_ci_high
A15: demographic_logistic | B15: Non-Hispanic White | C15: diagnosed | D15: 2022 | E15: 203 | F15: 1819 | G15: 104.60038 | H15: OK | I15: 0.87188141 | J15: 0.79665667 | K15: 0.96557958 | L15: 0.53138465 | M15: 0.49313205 | N15: 0.56938456 | O15: 0.14285304 | P15: 0.97888319 | Q15: =1-L15 -> 0.46861535 | R15: =1-N15 -> 0.43061544 | S15: =1-M15 -> 0.50686795
A16: demographic_logistic | B16: Non-Hispanic Black | C16: diagnosed | D16: 1312 | E16: 181 | F16: 1131 | G16: 140.92246 | H16: OK | I16: 0.76135423 | J16: 0.66570666 | K16: 0.86590237 | L16: 0.65892198 | M16: 0.63884761 | N16: 0.67935681 | O16: 0.22462107 | P16: 0.95516628 | Q16: =1-L16 -> 0.34107802 | R16: =1-N16 -> 0.32064319 | S16: =1-M16 -> 0.36115239
A17: demographic_logistic | B17: Mexican American | C17: diagnosed | D17: 856 | E17: 112 | F17: 744 | G17: 70.726598 | H17: OK | I17: 0.66176296 | J17: 0.53169784 | K17: 0.8033725 | L17: 0.7567724 | M17: 0.6918175 | N17: 0.81414323 | O17: 0.20607633 | P17: 0.95912721 | Q17: =1-L17 -> 0.2432276 | R17: =1-N17 -> 0.18585677 | S17: =1-M17 -> 0.3081825
A18: demographic_logistic | B18: Other Hispanic | C18: diagnosed | D18: 546 | E18: 74 | F18: 472 | G18: 53.369088 | H18: OK | I18: 0.8449487 | J18: 0.7364611 | K18: 1 | L18: 0.67378831 | M18: 0.63395194 | N18: 0.71430611 | O18: 0.1850385 | P18: 0.9802414 | Q18: =1-L18 -> 0.32621169 | R18: =1-N18 -> 0.28569389 | S18: =1-M18 -> 0.36604806
A19: demographic_logistic | B19: Non-Hispanic Asian | C19: diagnosed | D19: 796 | E19: 102 | F19: 694 | G19: 88.868673 | H19: OK | I19: 0.87893978 | J19: 0.79688788 | K19: 0.95936866 | L19: 0.67316664 | M19: 0.61905825 | N19: 0.73367929 | O19: 0.25936187 | P19: 0.97714384 | Q19: =1-L19 -> 0.32683336 | R19: =1-N19 -> 0.26632071 | S19: =1-M19 -> 0.38094175
A20: demographic_logistic | B20: Other/Multiracial | C20: diagnosed | D20: 341 | E20: 39 | F20: 302 | G20: 16.269939 | H20: SMALL SAMPLE | I20: 0.87778687 | J20: 0.75173581 | K20: 0.94096668 | L20: 0.65591373 | M20: 0.58565086 | N20: 0.75547037 | O20: 0.21184559 | P20: 0.980785 | Q20: =1-L20 -> 0.34408627 | R20: =1-N20 -> 0.24452963 | S20: =1-M20 -> 0.41434914
A21: demographic_logistic | B21: All groups | C21: diagnosed | D21: 5873 | E21: 711 | F21: 5162 | G21: 271.0185 | H21: OK | I21: 0.83477904 | J21: 0.77966254 | K21: 0.8923653 | L21: 0.59146713 | M21: 0.56887024 | N21: 0.61672376 | O21: 0.16583834 | P21: 0.97356339 | Q21: =1-L21 -> 0.40853287 | R21: =1-N21 -> 0.38327624 | S21: =1-M21 -> 0.43112976
A22: demographic_logistic | B22: Non-Hispanic White | C22: hba1c_pos | D22: 2022 | E22: 203 | F22: 1819 | G22: 104.60038 | H22: OK | I22: 0.88911237 | J22: 0.82271902 | K22: 0.96622672 | L22: 0.521934 | M22: 0.48650511 | N22: 0.56073613 | O22: 0.14278105 | P22: 0.98133023 | Q22: =1-L22 -> 0.478066 | R22: =1-N22 -> 0.43926387 | S22: =1-M22 -> 0.51349489
A23: demographic_logistic | B23: Non-Hispanic Black | C23: hba1c_pos | D23: 1312 | E23: 181 | F23: 1131 | G23: 140.92246 | H23: OK | I23: 0.78192402 | J23: 0.68261268 | K23: 0.88456202 | L23: 0.65169184 | M23: 0.63124479 | N23: 0.6737017 | O23: 0.22561009 | P23: 0.95838146 | Q23: =1-L23 -> 0.34830816 | R23: =1-N23 -> 0.3262983 | S23: =1-M23 -> 0.36875521
A24: demographic_logistic | B24: Mexican American | C24: hba1c_pos | D24: 856 | E24: 112 | F24: 744 | G24: 70.726598 | H24: OK | I24: 0.67208882 | J24: 0.54804098 | K24: 0.80966554 | L24: 0.75800889 | M24: 0.6996733 | N24: 0.80705453 | O24: 0.20942175 | P24: 0.96037703 | Q24: =1-L24 -> 0.24199111 | R24: =1-N24 -> 0.19294547 | S24: =1-M24 -> 0.3003267
A25: demographic_logistic | B25: Other Hispanic | C25: hba1c_pos | D25: 546 | E25: 74 | F25: 472 | G25: 53.369088 | H25: OK | I25: 0.86479537 | J25: 0.76859191 | K25: 1 | L25: 0.67704955 | M25: 0.62825779 | N25: 0.71755006 | O25: 0.19016478 | P25: 0.98279191 | Q25: =1-L25 -> 0.32295045 | R25: =1-N25 -> 0.28244994 | S25: =1-M25 -> 0.37174221
A26: demographic_logistic | B26: Non-Hispanic Asian | C26: hba1c_pos | D26: 796 | E26: 102 | F26: 694 | G26: 88.868673 | H26: OK | I26: 0.89713751 | J26: 0.81436383 | K26: 0.98740822 | L26: 0.66443113 | M26: 0.61308318 | N26: 0.71504945 | O26: 0.25823386 | P26: 0.98024181 | Q26: =1-L26 -> 0.33556887 | R26: =1-N26 -> 0.28495055 | S26: =1-M26 -> 0.38691682
... A70: extended_boosting | B70: All groups | C70: hba1c_pos | D70: 5873 | E70: 711 | F70: 5162 | G70: 271.0185 | H70: OK | I70: 0.82411968 | J70: 0.78993281 | K70: 0.86267755 | L70: 0.68889681 | M70: 0.67197351 | N70: 0.70762476 | O70: 0.20510743 | P70: 0.97577426 | Q70: =1-L70 -> 0.31110319 | R70: =1-N70 -> 0.29237524 | S70: =1-M70 -> 0.32802649
A74: False-positive burden of the HbA1c label versus the diagnosed label
A75: model | B75: group | C75: specificity_diagnosed | D75: specificity_hba1c | E75: cost | F75: cost_ci_low | G75: cost_ci_high | H75: fpr_diagnosed_label | I75: fpr_hba1c_label | J75: extra_false_positives_per_100 | K75: cost_reconciles
A76: demographic_logistic | B76: Non-Hispanic White | C76: 0.53138465 | D76: 0.521934 | E76: 0.0094506531 | F76: -0.0010895024 | G76: 0.020739535 | H76: =1-C76 -> 0.46861535 | I76: =1-D76 -> 0.478066 | J76: =(I76-H76)*100 -> 0.94506531 | K76: =IF(ABS((C76-D76)-E76)<=1e-06,"PASS","FAIL") -> PASS
A77: demographic_logistic | B77: Non-Hispanic Black | C77: 0.65892198 | D77: 0.65169184 | E77: 0.0072301373 | F77: -0.0085120454 | G77: 0.020611929 | H77: =1-C77 -> 0.34107802 | I77: =1-D77 -> 0.34830816 | J77: =(I77-H77)*100 -> 0.72301373 | K77: =IF(ABS((C77-D77)-E77)<=1e-06,"PASS","FAIL") -> PASS
A78: demographic_logistic | B78: Mexican American | C78: 0.7567724 | D78: 0.75800889 | E78: -0.0012364873 | F78: -0.016909106 | G78: 0.014819571 | H78: =1-C78 -> 0.2432276 | I78: =1-D78 -> 0.24199111 | J78: =(I78-H78)*100 -> -0.12364873 | K78: =IF(ABS((C78-D78)-E78)<=1e-06,"PASS","FAIL") -> PASS
A79: demographic_logistic | B79: Other Hispanic | C79: 0.67378831 | D79: 0.67704955 | E79: -0.0032612344 | F79: -0.026491641 | G79: 0.021451257 | H79: =1-C79 -> 0.32621169 | I79: =1-D79 -> 0.32295045 | J79: =(I79-H79)*100 -> -0.32612344 | K79: =IF(ABS((C79-D79)-E79)<=1e-06,"PASS","FAIL") -> PASS
A80: demographic_logistic | B80: Non-Hispanic Asian | C80: 0.67316664 | D80: 0.66443113 | E80: 0.008735516 | F80: -0.0076863366 | G80: 0.0250008 | H80: =1-C80 -> 0.32683336 | I80: =1-D80 -> 0.33556887 | J80: =(I80-H80)*100 -> 0.8735516 | K80: =IF(ABS((C80-D80)-E80)<=1e-06,"PASS","FAIL") -> PASS
A81: demographic_logistic | B81: Other/Multiracial | C81: 0.65591373 | D81: 0.64835596 | E81: 0.0075577695 | F81: -0.0061361284 | G81: 0.022558604 | H81: =1-C81 -> 0.34408627 | I81: =1-D81 -> 0.35164404 | J81: =(I81-H81)*100 -> 0.75577695 | K81: =IF(ABS((C81-D81)-E81)<=1e-06,"PASS","FAIL") -> PASS
A82: demographic_logistic | B82: All groups | C82: 0.59146713 | D82: 0.58436111 | E82: 0.0071060243 | F82: -0.0030141822 | G82: 0.018115901 | H82: =1-C82 -> 0.40853287 | I82: =1-D82 -> 0.41563889 | J82: =(I82-H82)*100 -> 0.71060243 | K82: =IF(ABS((C82-D82)-E82)<=1e-06,"PASS","FAIL") -> PASS
A83: demographic_race_logistic | B83: Non-Hispanic White | C83: 0.58410678 | D83: 0.60341443 | E83: -0.019307654 | F83: -0.036867154 | G83: -0.0011592339 | H83: =1-C83 -> 0.41589322 | I83: =1-D83 -> 0.39658557 | J83: =(I83-H83)*100 -> -1.9307654 | K83: =IF(ABS((C83-D83)-E83)<=1e-06,"PASS","FAIL") -> PASS
A84: demographic_race_logistic | B84: Non-Hispanic Black | C84: 0.65411208 | D84: 0.55435847 | E84: 0.099753617 | F84: 0.085736919 | G84: 0.11215376 | H84: =1-C84 -> 0.34588792 | I84: =1-D84 -> 0.44564153 | J84: =(I84-H84)*100 -> 9.9753617 | K84: =IF(ABS((C84-D84)-E84)<=1e-06,"PASS","FAIL") -> PASS
A85: demographic_race_logistic | B85: Mexican American | C85: 0.69260628 | D85: 0.64008097 | E85: 0.052525311 | F85: 0.033156444 | G85: 0.068578082 | H85: =1-C85 -> 0.30739372 | I85: =1-D85 -> 0.35991903 | J85: =(I85-H85)*100 -> 5.2525311 | K85: =IF(ABS((C85-D85)-E85)<=1e-06,"PASS","FAIL") -> PASS
A86: demographic_race_logistic | B86: Other Hispanic | C86: 0.73566735 | D86: 0.64829968 | E86: 0.087367667 | F86: 0.058887662 | G86: 0.1104865 | H86: =1-C86 -> 0.26433265 | I86: =1-D86 -> 0.35170032 | J86: =(I86-H86)*100 -> 8.7367667 | K86: =IF(ABS((C86-D86)-E86)<=1e-06,"PASS","FAIL") -> PASS
A87: demographic_race_logistic | B87: Non-Hispanic Asian | C87: 0.63918931 | D87: 0.54854247 | E87: 0.090646841 | F87: 0.070068078 | G87: 0.11436798 | H87: =1-C87 -> 0.36081069 | I87: =1-D87 -> 0.45145753 | J87: =(I87-H87)*100 -> 9.0646841 | K87: =IF(ABS((C87-D87)-E87)<=1e-06,"PASS","FAIL") -> PASS
... A103: extended_boosting | B103: All groups | C103: 0.66665225 | D103: 0.68889681 | E103: -0.022244562 | F103: -0.037068081 | G103: -0.0084033658 | H103: =1-C103 -> 0.33334775 | I103: =1-D103 -> 0.31110319 | J103: =(I103-H103)*100 -> -2.2244562 | K103: =IF(ABS((C103-D103)-E103)<=1e-06,"PASS","FAIL") -> PASS
A105: Extra false positives per 100 is the change in false positives per 100 HbA1c-negative people when the model is trained on the HbA1c label instead of the diagnosed label. Positive means more false positives.

Sheet Data_Quality
A1: NHANES 2017-2018 public-use survey data. Descriptive care-gap monitoring, not a certified quality measure, not clinical guidance, and no respondent-level rows.
A2: Data quality: pipeline checks, missingness, duplicates and source file hashes
A3: Checks come from data_quality.csv (SQL suites run on every build). Source hashes come from data/data_manifest.json.
A5: suite | B5: check | C5: status | D5: detail
A6: data_quality | B6: seqn_unique | C6: PASS | D6: rows=5873 distinct=5873
A7: data_quality | B7: weights_positive | C7: PASS | D7: min weight=3534.0362393758346
A8: data_quality | B8: psu_masked_values | C8: PASS | D8: rows with psu not in (1,2)=0
A9: data_quality | B9: no_lonely_psu_strata | C9: PASS | D9: min PSUs per stratum=2
A10: data_quality | B10: race_categories_allowed | C10: PASS | D10: unexpected categories=0
A11: data_quality | B11: diagnosed_is_binary | C11: PASS | D11: non-binary rows=0
A12: data_quality | B12: hba1c_present_and_plausible | C12: PASS | D12: rows with hba1c null or outside 3..20=0
A13: data_quality | B13: hba1c_positive_group_present | C13: PASS | D13: hba1c positives=711
A14: data_quality | B14: age_in_survey_range | C14: PASS | D14: rows outside 12..80=0
A15: data_quality | B15: missingness_reported | C15: PASS | D15: bmi=92 insured=14 routine_care=2 family_history=1086
A16: cohort_validation | B16: attrition_never_increases | C16: PASS | D16: steps that add rows=0
... A19: cohort_validation | B19: first_step_equals_demo_rows | C19: PASS | D19: demo rows=9254
A20: Checks passing | C20: =COUNTIF(C6:C19,"PASS")&" of "&ROWS(C6:C19) -> 14 of 14
A23: Missingness by group and input variable (refused, do not know, not asked or blank)
A24: group | B24: variable | C24: respondents | D24: missing | E24: missing_share | F24: missing_share_check | G24: missing_reconciles
A25: Non-Hispanic White | B25: bmi | C25: 2022 | D25: 29 | E25: 0.014342235 | F25: =D25/C25 -> 0.014342235 | G25: =IF(ABS(F25-E25)<=1e-06,"PASS","FAIL") -> PASS
A26: Non-Hispanic White | B26: family_history | C26: 2022 | D26: 341 | E26: 0.16864491 | F26: =D26/C26 -> 0.16864491 | G26: =IF(ABS(F26-E26)<=1e-06,"PASS","FAIL") -> PASS
A27: Non-Hispanic White | B27: insured | C27: 2022 | D27: 0 | E27: 0 | F27: =D27/C27 -> 0 | G27: =IF(ABS(F27-E27)<=1e-06,"PASS","FAIL") -> PASS
A28: Non-Hispanic White | B28: routine_care | C28: 2022 | D28: 1 | E28: 0.00049455984 | F28: =D28/C28 -> 0.00049455984 | G28: =IF(ABS(F28-E28)<=1e-06,"PASS","FAIL") -> PASS
A29: Non-Hispanic Black | B29: bmi | C29: 1312 | D29: 22 | E29: 0.016768293 | F29: =D29/C29 -> 0.016768293 | G29: =IF(ABS(F29-E29)<=1e-06,"PASS","FAIL") -> PASS
A30: Non-Hispanic Black | B30: family_history | C30: 1312 | D30: 225 | E30: 0.1714939 | F30: =D30/C30 -> 0.1714939 | G30: =IF(ABS(F30-E30)<=1e-06,"PASS","FAIL") -> PASS
A31: Non-Hispanic Black | B31: insured | C31: 1312 | D31: 5 | E31: 0.0038109756 | F31: =D31/C31 -> 0.0038109756 | G31: =IF(ABS(F31-E31)<=1e-06,"PASS","FAIL") -> PASS
A32: Non-Hispanic Black | B32: routine_care | C32: 1312 | D32: 0 | E32: 0 | F32: =D32/C32 -> 0 | G32: =IF(ABS(F32-E32)<=1e-06,"PASS","FAIL") -> PASS
A33: Mexican American | B33: bmi | C33: 856 | D33: 13 | E33: 0.015186916 | F33: =D33/C33 -> 0.015186916 | G33: =IF(ABS(F33-E33)<=1e-06,"PASS","FAIL") -> PASS
A34: Mexican American | B34: family_history | C34: 856 | D34: 196 | E34: 0.22897196 | F34: =D34/C34 -> 0.22897196 | G34: =IF(ABS(F34-E34)<=1e-06,"PASS","FAIL") -> PASS
A35: Mexican American | B35: insured | C35: 856 | D35: 7 | E35: 0.0081775701 | F35: =D35/C35 -> 0.0081775701 | G35: =IF(ABS(F35-E35)<=1e-06,"PASS","FAIL") -> PASS
A36: Mexican American | B36: routine_care | C36: 856 | D36: 0 | E36: 0 | F36: =D36/C36 -> 0 | G36: =IF(ABS(F36-E36)<=1e-06,"PASS","FAIL") -> PASS
... A52: All groups | B52: routine_care | C52: 5873 | D52: 2 | E52: 0.00034054146 | F52: =D52/C52 -> 0.00034054146 | G52: =IF(ABS(F52-E52)<=1e-06,"PASS","FAIL") -> PASS
A56: Source files: CDC NHANES 2017-2018 public-use data (hashes verified on download)
A57: file | B57: source_url | C57: bytes | D57: sha256 | E57: retrieved_at | F57: columns_verified
A58: BMX_J | B58: https://wwwn.cdc.gov/Nchs/Data/Nhanes/Public/2017/DataFiles/BMX_J.xpt | C58: 1466000 | D58: 8d675e42d8826ac98714b2c3dd4c5138a5e353fb4424f7eff5e6db4a01ce838a | E58: 2026-09-19 | F58: SEQN, BMXBMI
A59: DEMO_J | B59: https://wwwn.cdc.gov/Nchs/Data/Nhanes/Public/2017/DataFiles/DEMO_J.xpt | C59: 3412720 | D59: c0b46e0345ea19404928656277c8b0d10b0cca348a9b2fe4fc3c67e8b7ee73ec | E59: 2026-09-19 | F59: SEQN, RIDAGEYR, RIAGENDR, RIDRETH3, WTMEC2YR, SDMVPSU, SDMVSTRA
A60: DIQ_J | B60: https://wwwn.cdc.gov/Nchs/Data/Nhanes/Public/2017/DataFiles/DIQ_J.xpt | C60: 3851840 | D60: 1ecbf5360dfc331d1efbf32198553dc30e9a1f4cff0a907ed30ca72bac797f89 | E60: 2026-09-19 | F60: SEQN, DIQ010
A61: GHB_J | B61: https://wwwn.cdc.gov/Nchs/Data/Nhanes/Public/2017/DataFiles/GHB_J.xpt | C61: 103520 | D61: 35f07094573a0061a03ed609a5a363b34eb1b1c7065d1623b43d72e132a8a654 | E61: 2026-09-19 | F61: SEQN, LBXGH
A62: HIQ_J | B62: https://wwwn.cdc.gov/Nchs/Data/Nhanes/Public/2017/DataFiles/HIQ_J.xpt | C62: 1187520 | D62: 96dfdd98507ea6dc67cb2c2b6999da3c035f3f8a9a87cf34756fe30762387860 | E62: 2026-09-19 | F62: SEQN, HIQ011
A63: HUQ_J | B63: https://wwwn.cdc.gov/Nchs/Data/Nhanes/Public/2017/DataFiles/HUQ_J.xpt | C63: 742480 | D63: 0d8814ca6a72c003eb89885a3a24dcff3b475dfed454089cf4890f9ab9da06d2 | E63: 2026-09-19 | F63: SEQN, HUQ030
...

Sheet Metric_Dictionary
A1: NHANES 2017-2018 public-use survey data. Descriptive care-gap monitoring, not a certified quality measure, not clinical guidance, and no respondent-level rows.
A2: Metric dictionary: numerator, denominator, exclusions, unit and source
A3: Definitions live in configs/metric_dictionary.yml and are shared with the stakeholder brief and the Tableau field dictionary.
A5: id | B5: name | C5: definition | D5: numerator | E5: denominator | F5: exclusions | G5: unit | H5: source
A6: undiagnosed_share | B6: Undiagnosed share | C6: Weighted share of people meeting the HbA1c criterion who were never told by a doctor that they have diabetes. | D6: Respondents with HbA1c at or above the threshold who answered no to "a doctor told you that you have diabetes" (DIQ010 = 2), weighted by WTMEC2YR. | E6: Respondents with HbA1c at or above the threshold (LBXGH >= 6.5), weighted by WTMEC2YR. | F6: No valid diabetes answer (refused, do not know, missing); borderline answers (DIQ010 = 3) in the main analysis; HbA1c not measured; unknown race and ethnicity. | G6: Proportion, shown as a percentage. Interval is a 95% logit interval on design degrees of freedom. | H6: outputs/tables/undiagnosis_estimates.csv (estimate, ci_low_logit, ci_high_logit)
A7: weighted_undiagnosed_people | B7: People with undiagnosed diabetes, weighted | C7: Survey-weighted count of people meeting the HbA1c criterion who were never told they have diabetes. | D7: Sum of WTMEC2YR over HbA1c-positive respondents who answered no to being told they have diabetes. | E7: Not applicable (a weighted count). | F7: Same as undiagnosed share. | G7: People represented by the survey weights. No interval is reported. | H7: outputs/tables/group_summary.csv (weighted_undiagnosed)
A8: undiagnosed_gap | B8: Undiagnosed share difference versus reference group | C8: Undiagnosed share of a group minus the undiagnosed share of the reference group (Non-Hispanic White). | D8: Group undiagnosed share minus reference undiagnosed share, from a joint linearization of the two ratios. | E8: Not applicable (a difference); the ratio column divides the two shares. | F8: Same as undiagnosed share. | G8: Percentage points, shown as a percentage. Only the Non-Hispanic Black comparison is confirmatory; the others are exploratory with Holm-adjusted p-values. | H8: outputs/tables/undiagnosis_contrasts.csv (difference, ci_low, ci_high, p_value, p_value_holm)
A9: effective_n | B9: Effective sample size | C9: Kish effective sample size of the HbA1c-positive respondents in a group, which shrinks when weights are unequal. | D9: (sum of weights) squared. | E9: Sum of squared weights. | F9: Same as undiagnosed share. | G9: Respondents. A group with fewer than 30 respondents or an effective n under 30 carries a small-sample warning. | H9: outputs/tables/undiagnosis_estimates.csv (effective_n_kish, small_n_warning)
A10: auc | B10: AUC against the HbA1c criterion | C10: Weighted area under the ROC curve of out-of-fold predictions, scored against the HbA1c criterion. | D10: Not applicable. | E10: Not applicable. | F10: Same cohort as undiagnosed share, but all cohort respondents (HbA1c-positive and negative). | G10: Area under the curve, 0.5 to 1. Interval is a Rao-Wu rescaled PSU bootstrap. | H10: outputs/tables/auc.csv (auc, ci_low, ci_high)
A11: auc_difference | B11: AUC difference between labels | C11: AUC of the model trained on the diagnosed label minus AUC of the model trained on the HbA1c label, both scored against the HbA1c criterion. | D11: Not applicable. | E11: Not applicable. | F11: Same as AUC. | G11: AUC points. Interval and p-value come from a paired bootstrap. | H11: outputs/tables/auc_difference.csv
A12: sensitivity | B12: Sensitivity | C12: Weighted share of HbA1c-positive respondents the model flags at its cross-validated threshold. | D12: Weighted HbA1c-positive respondents flagged by the model. | E12: Weighted HbA1c-positive respondents. | F12: Same as AUC. The threshold is chosen inside each training fold, never on the held-out fold. | G12: Proportion, shown as a percentage. | H12: outputs/tables/subgroup_metrics.csv (sensitivity, sensitivity_ci_low, sensitivity_ci_high)
A13: specificity | B13: Specificity | C13: Weighted share of HbA1c-negative respondents the model does not flag. | D13: Weighted HbA1c-negative respondents not flagged by the model. | E13: Weighted HbA1c-negative respondents. | F13: Same as AUC. | G13: Proportion, shown as a percentage. | H13: outputs/tables/subgroup_metrics.csv (specificity, specificity_ci_low, specificity_ci_high)
A14: false_positive_rate | B14: False-positive rate | C14: One minus specificity. The share of HbA1c-negative respondents the model would flag for follow-up. | D14: Weighted HbA1c-negative respondents flagged by the model. | E14: Weighted HbA1c-negative respondents. | F14: Same as AUC. | G14: Proportion, shown as a percentage. Computed as a live formula in the workbook. | H14: outputs/tables/specificity_cost.csv (1 - specificity_diagnosed, 1 - specificity_hba1c)
A15: specificity_cost | B15: Specificity cost of the HbA1c label | C15: Specificity of the model trained on the diagnosed label minus specificity of the model trained on the HbA1c label. Positive means more false positives when training on the HbA1c label. | D15: Not applicable. | E15: Not applicable. | F15: Same as AUC. | G15: Percentage points, shown as a percentage. Interval is a paired bootstrap. | H15: outputs/tables/specificity_cost.csv (cost, ci_low, ci_high)
A16: holm_adjusted_p | B16: Holm-adjusted p-value | C16: p-value of a group comparison after Holm adjustment across the five comparisons with the reference group. | D16: Not applicable. | E16: Not applicable. | F16: Same as undiagnosed share. | G16: Probability. A group comparison is labelled exploratory unless it is the pre-specified contrast. | H16: outputs/tables/undiagnosis_contrasts.csv (p_value_holm, analysis_type)
A17: missingness | B17: Missingness share | C17: Share of respondents in a group with no valid value for an input variable. | D17: Respondents in the group with the variable missing (refused, do not know, not asked or blank). | E17: Respondents in the group in the analysis cohort. | F17: None. | G17: Proportion, shown as a percentage. Computed as a live formula in the workbook. | H17: outputs/tables/missingness_by_group.csv
